<?xml version="1.0" ?>
<!-- =================================================================================== -->
<!-- |    This document was autogenerated by xacro from xacro/base_robot.xacro         | -->
<!-- |    EDITING THIS FILE BY HAND IS NOT RECOMMENDED                                 | -->
<!-- =================================================================================== -->
<robot xmlns="http://drake.mit.edu">
  <link name="base_link"/>
  <joint name="odrive_joint" type="fixed">
    <parent link="base_link"/>
    <child link="odrive_base"/>
  </joint>
  <link name="odrive_base">
    <visual>
      <geometry>
        <cylinder length="0.1615" radius="0.09"/>
      </geometry>
      <material name="blue">
        <color rgba="0 0 1 1"/>
      </material>
      <origin xyz="0 0 0.08075"/>
    </visual>
    <!-- <collision>
            <geometry>
                <cylinder length="${height}" radius="${radius}"/>
            </geometry>
            <origin xyz="0 0 ${height/2}"/>
        </collision> -->
  </link>
  <joint name="shoulder" type="revolute">
    <parent link="odrive_base"/>
    <child link="upperarm"/>
    <origin xyz="0 0 0.1615"/>
    <axis xyz="0 0 1"/>
    <limit effort=".1" lower="-3.141592653589793" upper="3.141592653589793" velocity="20"/>
    <!-- <limit drake:acceleration="8.57" effort="320" lower="-2.96705972839" upper="2.96705972839" velocity="1.4835298641951802"/> -->
    <!-- <dynamics damping="0.5"/> -->
  </joint>
  <link name="upperarm">
    <visual>
      <geometry>
        <box size="0.30381 0.070471 0.070471"/>
      </geometry>
      <origin xyz="0.151905 0 0.0352355"/>
      <material name="green">
        <color rgba="0 1 0 1"/>
      </material>
    </visual>
    <!-- <collision>
            <geometry>
                <box size="${length} ${height} ${height}"/>
            </geometry>
            <origin xyz="0 ${length/2} ${height/2}" />
        </collision> -->
    <inertial>
      <mass value="0.982"/>
      <!-- In the Articulated Robot video, his xyz here is x, 0, z. Why? -->
      <origin xyz="0.151905 0 0.0352355"/>
      <inertia ixx="0.0008127951546436667" ixy="0.0" ixz="0.0" iyy="0.007959656478171834" iyz="0.0" izz="0.007959656478171834"/>
    </inertial>
  </link>
  <joint name="elbow" type="revolute">
    <parent link="upperarm"/>
    <child link="forearm"/>
    <origin xyz="0.30381 0 0.070471"/>
    <axis xyz="0 0 1"/>
    <limit effort=".1" lower="-3.141592653589793" upper="3.141592653589793" velocity="20"/>
    <!-- <limit drake:acceleration="8.57" effort="320" lower="-2.96705972839" upper="2.96705972839" velocity="1.4835298641951802"/>
        <dynamics damping="0.5"/> -->
  </joint>
  <link name="forearm">
    <visual>
      <geometry>
        <box size="0.259916 0.02545 0.02545"/>
      </geometry>
      <origin xyz="0.129958 0 0.012725"/>
      <material name="red">
        <color rgba="1 0 0 1"/>
      </material>
    </visual>
    <!-- <collision>
            <geometry>
                <box size="${length} ${height} ${height}"/>
            </geometry>
            <origin xyz="0 ${length/2} ${height/2}" />
        </collision> -->
    <inertial>
      <mass value="0.6"/>
      <!-- In the Articulated Robot video, his xyz here is x, 0, z. Why? -->
      <origin xyz="0.129958 0 0.012725"/>
      <inertia ixx="6.477025e-05" ixy="0.0" ixz="0.0" iyy="0.0034102014777999995" iyz="0.0" izz="0.0034102014777999995"/>
    </inertial>
  </link>
  <joint name="wrist_orbit" type="revolute">
    <parent link="forearm"/>
    <child link="wrist_bone"/>
    <origin rpy="0 0 0" xyz="0.259916 0 0.012725"/>
    <axis xyz="0 0 1"/>
    <limit effort=".1" lower="-1.5707963267948966" upper="1.5707963267948966" velocity="20"/>
  </joint>
  <link name="wrist_bone">
    <visual>
      <geometry>
        <sphere radius="0.005"/>
      </geometry>
      <material name="blue">
        <color rgba="0 0 1 1"/>
      </material>
      <origin rpy="0 0 0" xyz="0.005 0 0"/>
    </visual>
    <!-- <collision>
            <geometry>
                <cylinder length="${height}" radius="${radius}"/>
            </geometry>
            <origin xyz="0 ${radius} 0" rpy="0 ${pi/2} 0"/>
        </collision> -->
    <inertial>
      <mass value="0.01"/>
      <!-- In the Articulated Robot video, his xyz here is x, 0, z. Why? -->
      <origin rpy="0 0 0" xyz="0 0.08 0"/>
      <inertia ixx="1.0666666666666667e-05" ixy="0.0" ixz="0.0" iyy="5.416666666666667e-06" iyz="0.0" izz="5.416666666666667e-06"/>
    </inertial>
  </link>
  <joint name="wrist_spin" type="revolute">
    <parent link="wrist_bone"/>
    <child link="end_effector"/>
    <origin rpy="0 0 0" xyz="0.01 0 0"/>
    <axis xyz="1 0 0"/>
    <limit effort=".1" lower="-12.566370614359172" upper="12.566370614359172" velocity="20"/>
  </joint>
  <link name="end_effector">
    <visual>
      <geometry>
        <cylinder length="0.01" radius="0.08"/>
      </geometry>
      <material name="blue">
        <color rgba="0 0 1 1"/>
      </material>
      <origin rpy="1.5707963267948966 0 0" xyz="0.08 0 0"/>
    </visual>
    <!-- <collision>
            <geometry>
                <cylinder length="${height}" radius="${radius}"/>
            </geometry>
            <origin xyz="0 ${radius} 0" rpy="0 ${pi/2} 0"/>
        </collision> -->
    <inertial>
      <mass value="0.158"/>
      <!-- In the Articulated Robot video, his xyz here is x, 0, z. Why? -->
      <origin rpy="0 0 0" xyz="0 0.08 0"/>
      <inertia ixx="0.00016853333333333336" ixy="0.0" ixz="0.0" iyy="8.558333333333334e-05" iyz="0.0" izz="8.558333333333334e-05"/>
    </inertial>
  </link>
  <transmission name="shoulder_torque" type="SimpleTransmission">
    <actuator name="shoulder_input"/>
    <joint name="shoulder"/>
  </transmission>
  <transmission name="elbow_torque" type="SimpleTransmission">
    <actuator name="elbow_input"/>
    <joint name="elbow"/>
  </transmission>
  <transmission name="wrist_torque" type="SimpleTransmission">
    <actuator name="wrist_input"/>
    <joint name="wrist"/>
  </transmission>
</robot>
